Workbook

Sheet Assumptions
A1: Financial Model - Assumptions
A3: TRAFFIC & ACQUISITION
A4: Site Traffic
A5: Total annual site visits – Year 1 | B5: 25000
A6: Annual traffic growth (YoY %) | B6: 0.2
A8: Channel Mix
A9: % of visits – paid acquisition | B9: 0.5
A10: % of visits – organic & direct | B10: 0.15
A11: % of visits – retention (email & SMS) | B11: 0.35
A12: Channel mix check (should = 100%) | B12: =SUM(B9:B11) -> 1
A14: Conversion Rates
A15: Conversion rate – paid acquisition | B15: 0.15
A16: Conversion rate – organic & direct | B16: 0.35
A17: Conversion rate – retention (email & SMS) | B17: 0.5
A19: REPEAT PURCHASES
A20: Repeat purchase rate – Year 1 | B20: 0.25
A21: Repeat purchase frequency (orders/yr) | B21: 2
A22: Annual retention improvement % | B22: 0.05
A24: ORDER ECONOMICS
A25: Average order value (gross) – Year 1 | B25: 250
A26: AOV inflation (%) | B26: 0.1
A27: Cost of goods sold (%) | B27: 0.5
A28: Annual COGS improvement % | B28: 0.01
A29: Discounts & promos (%) | B29: 0.1
A30: Return/refund rate (%) | B30: 0.1
A31: Payment processing fee (%) | B31: 0.029
A32: Marketplace/platform fee (%) | B32: 0
A34: MARKETING
A35: Paid acquisition CPC – Year 1 | B35: 5.75
A36: CPC inflation (%) | B36: 0.05
A38: FULFILMENT
A39: Shipping cost per order – Year 1 | B39: 12
A40: Shipping cost inflation (%) | B40: 0.02
A41: Handling cost per order – Year 1 | B41: 5
A42: Packaging cost per order | B42: 1.5
A43: Customer support cost per order | B43: 1.5
A45: WAREHOUSE
A46: Warehouse rent amount (when active) | B46: 150000
A47: Warehouse rent – start year | B47: 2027
A48: Warehouse rent – annual inflation (%) | B48: 0.05
...

Sheet Model
E1: Startup year
E2: 2026 | F2: =+E2+1 -> 2027 | G2: =+F2+1 -> 2028 | H2: =+G2+1 -> 2029 | I2: =+H2+1 -> 2030 | J2: =+I2+1 -> 2031
A3: Balance sheet check | E3: =IFERROR(IF(ABS(E194)>1,"ERROR","OK"),"OK") -> OK | F3: =IFERROR(IF(ABS(F194)>1,"ERROR","OK"),"OK") -> OK | G3: =IFERROR(IF(ABS(G194)>1,"ERROR","OK"),"OK") -> OK | H3: =IFERROR(IF(ABS(H194)>1,"ERROR","OK"),"OK") -> OK | I3: =IFERROR(IF(ABS(I194)>1,"ERROR","OK"),"OK") -> OK | J3: =IFERROR(IF(ABS(J194)>1,"ERROR","OK"),"OK") -> OK
A5: Assumptions
A7: Acquisition Channels
A8: Site traffic
A9: Total annual site visits – Year 1 | D9: =Assumptions!B5 -> 25000
A10: Annual traffic growth (YoY %) | D10: =Assumptions!B6 -> 0.2
A12: Channel mix
A13: % of visits – paid acquisition | D13: =Assumptions!B9 -> 0.5
A14: % of visits – organic & direct | D14: =Assumptions!B10 -> 0.15
A15: % of visits – retention (email & SMS) | D15: =Assumptions!B11 -> 0.35
A16: Total traffic mix | D16: =SUM(D13:D15) -> 1
A18: Traffic by channel
A19: Paid acquisition | E19: =$D$9*$D13 -> 12500 | F19: =E19*(1+$D$10) -> 15000 | G19: =F19*(1+$D$10) -> 18000 | H19: =G19*(1+$D$10) -> 21600 | I19: =H19*(1+$D$10) -> 25920 | J19: =I19*(1+$D$10) -> 31104
A20: Organic & direct | E20: =$D$9*$D14 -> 3750 | F20: =E20*(1+$D$10) -> 4500 | G20: =F20*(1+$D$10) -> 5400 | H20: =G20*(1+$D$10) -> 6480 | I20: =H20*(1+$D$10) -> 7776 | J20: =I20*(1+$D$10) -> 9331.2
A21: Retention (email & SMS) | E21: =$D$9*$D15 -> 8750 | F21: =E21*(1+$D$10) -> 10500 | G21: =F21*(1+$D$10) -> 12600 | H21: =G21*(1+$D$10) -> 15120 | I21: =H21*(1+$D$10) -> 18144 | J21: =I21*(1+$D$10) -> 21772.8
A22: Total annual visits | E22: =D9 -> 25000 | F22: =E22*(1+$D$10) -> 30000 | G22: =F22*(1+$D$10) -> 36000 | H22: =G22*(1+$D$10) -> 43200 | I22: =H22*(1+$D$10) -> 51840 | J22: =I22*(1+$D$10) -> 62208
A24: Orders Placed
A25: Conversion rates
A26: Conversion rate – paid acquisition | D26: =Assumptions!B15 -> 0.15
A27: Conversion rate – organic & direct | D27: =Assumptions!B16 -> 0.35
A28: Conversion rate – retention (email & SMS) | D28: =Assumptions!B17 -> 0.5
A29: Repeat purchase rate – Year 1 | D29: =Assumptions!B20 -> 0.25
A30: Repeat purchase frequency (orders/yr) | D30: =Assumptions!B21 -> 2
A31: Annual retention improvement % | D31: =Assumptions!B22 -> 0.05
A33: Orders by channel
A34: Paid acquisition | E34: =E19*$D26 -> 1875 | F34: =F19*$D26 -> 2250 | G34: =G19*$D26 -> 2700 | H34: =H19*$D26 -> 3240 | I34: =I19*$D26 -> 3888 | J34: =J19*$D26 -> 4665.6
A35: Organic & direct | E35: =E20*$D27 -> 1312.5 | F35: =F20*$D27 -> 1575 | G35: =G20*$D27 -> 1890 | H35: =H20*$D27 -> 2268 | I35: =I20*$D27 -> 2721.6 | J35: =J20*$D27 -> 3265.92
A36: Retention (email & SMS) | E36: =E21*$D28 -> 4375 | F36: =F21*$D28 -> 5250 | G36: =G21*$D28 -> 6300 | H36: =H21*$D28 -> 7560 | I36: =I21*$D28 -> 9072 | J36: =J21*$D28 -> 10886.4
A37: New orders (from traffic) | E37: =SUM(E34:E36) -> 7562.5 | F37: =SUM(F34:F36) -> 9075 | G37: =SUM(G34:G36) -> 10890 | H37: =SUM(H34:H36) -> 13068 | I37: =SUM(I34:I36) -> 15681.6 | J37: =SUM(J34:J36) -> 18817.92
A38: Cumulative new customers (prior years) | E38: 0 | F38: =E37 -> 7562.5 | G38: =E37+F37 -> 16637.5 | H38: =SUM($E$37:G37) -> 27527.5 | I38: =SUM($E$37:H37) -> 40595.5 | J38: =SUM($E$37:I37) -> 56277.1
A39: Effective repeat rate | E39: =$D$29 -> 0.25 | F39: =$D$29*(1+$D$31)^1 -> 0.2625 | G39: =$D$29*(1+$D$31)^2 -> 0.275625 | H39: =$D$29*(1+$D$31)^3 -> 0.28940625 | I39: =$D$29*(1+$D$31)^4 -> 0.30387656 | J39: =$D$29*(1+$D$31)^5 -> 0.31907039
A40: Repeat orders | E40: 0 | F40: =F38*F39*$D$30 -> 3970.3125 | G40: =G38*G39*$D$30 -> 9171.4219 | H40: =H38*H39*$D$30 -> 15933.261 | I40: =I38*I39*$D$30 -> 24672.042 | J40: =J38*J39*$D$30 -> 35912.713
A41: Gross orders (new + repeat) | E41: =E37+E40 -> 7562.5 | F41: =F37+F40 -> 13045.312 | G41: =G37+G40 -> 20061.422 | H41: =H37+H40 -> 29001.261 | I41: =I37+I40 -> 40353.642 | J41: =J37+J40 -> 54730.633
A43: Order Details
A44: Average order value (gross) – Year 1 | D44: =Assumptions!B25 -> 250
A45: AOV inflation (%) | D45: =Assumptions!B26 -> 0.1
A46: Cost of goods sold (%) | D46: =Assumptions!B27 -> 0.5
A47: Annual COGS improvement % | D47: =Assumptions!B28 -> 0.01
...

Sheet Financial Statements
A1: Financial Statements
B2: 2026 | C2: 2027 | D2: 2028 | E2: 2029 | F2: 2030 | G2: 2031
A4: Income Statement
A6: Gross revenue | B6: =Model!E134 -> 1890625 | C6: =Model!F134 -> 3587460.9 | D6: =Model!G134 -> 6068580.1 | E6: =Model!H134 -> 9650169.6 | F6: =Model!I134 -> 14770442 | G6: =Model!J134 -> 22036058
A7: Less: Discounts & promotions | B7: =Model!E135 -> -189062.5 | C7: =Model!F135 -> -358746.09 | D7: =Model!G135 -> -606858.01 | E7: =Model!H135 -> -965016.96 | F7: =Model!I135 -> -1477044.2 | G7: =Model!J135 -> -2203605.8
A8: Less: Returns & refunds | B8: =Model!E136 -> -189062.5 | C8: =Model!F136 -> -358746.09 | D8: =Model!G136 -> -606858.01 | E8: =Model!H136 -> -965016.96 | F8: =Model!I136 -> -1477044.2 | G8: =Model!J136 -> -2203605.8
A9: Less: Platform fees | B9: =Model!E137 -> 0 | C9: =Model!F137 -> 0 | D9: =Model!G137 -> 0 | E9: =Model!H137 -> 0 | F9: =Model!I137 -> 0 | G9: =Model!J137 -> 0
A10: Less: Payment processing | B10: =Model!E138 -> -54828.125 | C10: =Model!F138 -> -104036.37 | D10: =Model!G138 -> -175988.82 | E10: =Model!H138 -> -279854.92 | F10: =Model!I138 -> -428342.81 | G10: =Model!J138 -> -639045.68
A11: Net revenue | B11: =Model!E139 -> 1457671.9 | C11: =Model!F139 -> 2765932.4 | D11: =Model!G139 -> 4678875.3 | E11: =Model!H139 -> 7440280.8 | F11: =Model!I139 -> 11388011 | G11: =Model!J139 -> 16989801
A13: Cost of goods sold | B13: =Model!E142 -> 945312.5 | C13: =Model!F142 -> 1775793.2 | D13: =Model!G142 -> 2973907.7 | E13: =Model!H142 -> 4681775 | F13: =Model!I142 -> 7094213.7 | G13: =Model!J142 -> 10478036
A14: Gross profit | B14: =Model!E143 -> 512359.38 | C14: =Model!F143 -> 990139.22 | D14: =Model!G143 -> 1704967.6 | E14: =Model!H143 -> 2758505.8 | F14: =Model!I143 -> 4293796.9 | G14: =Model!J143 -> 6511764.7
A15: Gross margin % | B15: =Model!E144 -> 0.35149157 | C15: =Model!F144 -> 0.35797665 | D15: =Model!G144 -> 0.36439689 | E15: =Model!H144 -> 0.37075292 | F15: =Model!I144 -> 0.37704539 | G15: =Model!J144 -> 0.38327494
A17: Variable operating expenses
A18: Marketing (paid acquisition) | B18: =Model!E147 -> 71875 | C18: =Model!F147 -> 90562.5 | D18: =Model!G147 -> 114108.75 | E18: =Model!H147 -> 143777.03 | F18: =Model!I147 -> 181159.05 | G18: =Model!J147 -> 228260.4
A19: Shipping & handling | B19: =Model!E148 -> 128562.5 | C19: =Model!F148 -> 226205.72 | D19: =Model!G148 -> 354822.36 | E19: =Model!H148 -> 523198.29 | F19: =Model!I148 -> 742561.36 | G19: =Model!J148 -> 1027259.7
A20: Packaging | B20: =Model!E149 -> 11343.75 | C20: =Model!F149 -> 19567.969 | D20: =Model!G149 -> 30092.133 | E20: =Model!H149 -> 43501.892 | F20: =Model!I149 -> 60530.463 | G20: =Model!J149 -> 82095.949
A21: Customer support | B21: =Model!E150 -> 11343.75 | C21: =Model!F150 -> 19567.969 | D21: =Model!G150 -> 30092.133 | E21: =Model!H150 -> 43501.892 | F21: =Model!I150 -> 60530.463 | G21: =Model!J150 -> 82095.949
A22: Total variable costs | B22: =Model!E151 -> 223125 | C22: =Model!F151 -> 355904.16 | D22: =Model!G151 -> 529115.37 | E22: =Model!H151 -> 753979.1 | F22: =Model!I151 -> 1044781.3 | G22: =Model!J151 -> 1419712
A23: Contribution margin | B23: =Model!E152 -> 289234.38 | C23: =Model!F152 -> 634235.06 | D23: =Model!G152 -> 1175852.2 | E23: =Model!H152 -> 2004526.7 | F23: =Model!I152 -> 3249015.6 | G23: =Model!J152 -> 5092052.7
A24: Contribution margin % | B24: =Model!E153 -> 0.19842214 | C24: =Model!F153 -> 0.22930245 | D24: =Model!G153 -> 0.25131087 | E24: =Model!H153 -> 0.26941547 | F24: =Model!I153 -> 0.28530142 | G24: =Model!J153 -> 0.29971233
A26: Fixed operating expenses
A27: Warehouse / fulfilment | B27: =Model!E156 -> 0 | C27: =Model!F156 -> 150000 | D27: =Model!G156 -> 157500 | E27: =Model!H156 -> 165375 | F27: =Model!I156 -> 173643.75 | G27: =Model!J156 -> 182325.94
A28: General & administrative | B28: =Model!E157 -> 278000 | C28: =Model!F157 -> 413150 | D28: =Model!G157 -> 428807.5 | E28: =Model!H157 -> 445247.88 | F28: =Model!I157 -> 462510.27 | G28: =Model!J157 -> 480635.78
A29: Total fixed costs | B29: =Model!E158 -> 278000 | C29: =Model!F158 -> 563150 | D29: =Model!G158 -> 586307.5 | E29: =Model!H158 -> 610622.88 | F29: =Model!I158 -> 636154.02 | G29: =Model!J158 -> 662961.72
A31: EBITDA | B31: =Model!E159 -> 11234.375 | C31: =Model!F159 -> 71085.062 | D31: =Model!G159 -> 589544.71 | E31: =Model!H159 -> 1393903.8 | F31: =Model!I159 -> 2612861.5 | G31: =Model!J159 -> 4429091
A32: EBITDA margin % | B32: =Model!E160 -> 0.0077070671 | C32: =Model!F160 -> 0.025700217 | D32: =Model!G160 -> 0.12600137 | E32: =Model!H160 -> 0.1873456 | F32: =Model!I160 -> 0.22943968 | G32: =Model!J160 -> 0.26069117
A34: Depreciation | B34: =Model!E162 -> 37812.5 | C34: =Model!F162 -> 109561.72 | D34: =Model!G162 -> 230933.32 | E34: =Model!H162 -> 423936.71 | F34: =Model!I162 -> 719345.55 | G34: =Model!J162 -> 1267566.5
A35: Interest expense | B35: =Model!E163 -> 0 | C35: =Model!F163 -> 0 | D35: =Model!G163 -> 0 | E35: =Model!H163 -> 0 | F35: =Model!I163 -> 0 | G35: =Model!J163 -> 0
A36: Earnings before tax (EBT) | B36: =Model!E164 -> -26578.125 | C36: =Model!F164 -> -38476.656 | D36: =Model!G164 -> 358611.39 | E36: =Model!H164 -> 969967.12 | F36: =Model!I164 -> 1893516 | G36: =Model!J164 -> 3161524.5
A38: Income tax | B38: =Model!E166 -> 0 | C38: =Model!F166 -> 0 | D38: =Model!G166 -> 89652.848 | E38: =Model!H166 -> 242491.78 | F38: =Model!I166 -> 473379 | G38: =Model!J166 -> 790381.11
A39: Net income | B39: =Model!E167 -> -26578.125 | C39: =Model!F167 -> -38476.656 | D39: =Model!G167 -> 268958.54 | E39: =Model!H167 -> 727475.34 | F39: =Model!I167 -> 1420137 | G39: =Model!J167 -> 2371143.3
A42: Balance Sheet
A44: ASSETS
A45: Cash | B45: =Model!E175 -> 87452.055 | C45: =Model!F175 -> -358918.29 | D45: =Model!G175 -> -656665.38 | E45: =Model!H175 -> -697641.59 | F45: =Model!I175 -> -303685.99 | G45: =Model!J175 -> 817671.64
A46: Accounts receivable | B46: =Model!E176 -> 19968.108 | C46: =Model!F176 -> 37889.485 | D46: =Model!G176 -> 64094.182 | E46: =Model!H176 -> 101921.65 | F46: =Model!I176 -> 156000.15 | G46: =Model!J176 -> 232736.99
A47: Inventory | B47: =Model!E177 -> 310787.67 | C47: =Model!F177 -> 530747.65 | D47: =Model!G177 -> 808035.6 | E47: =Model!H177 -> 1156434 | F47: =Model!I177 -> 1593022.5 | G47: =Model!J177 -> 2138970.7
A48: Total current assets | B48: =Model!E178 -> 418207.83 | C48: =Model!F178 -> 209718.84 | D48: =Model!G178 -> 215464.4 | E48: =Model!H178 -> 560714.1 | F48: =Model!I178 -> 1445336.7 | G48: =Model!J178 -> 3189379.3
A49: Property & equipment (PP&E, net) | B49: =Model!E179 -> 151250 | C49: =Model!F179 -> 400434.38 | D49: =Model!G179 -> 776359.07 | E49: =Model!H179 -> 1317439.3 | F49: =Model!I179 -> 2075137.9 | G49: =Model!J179 -> 3011177.2
A50: Total assets | B50: =Model!E180 -> 569457.83 | C50: =Model!F180 -> 610153.22 | D50: =Model!G180 -> 991823.47 | E50: =Model!H180 -> 1878153.4 | F50: =Model!I180 -> 3520474.6 | G50: =Model!J180 -> 6200556.5
A52: LIABILITIES
...

Sheet Dashboard
A1: Dashboard
B2: 2026 | C2: 2027 | D2: 2028 | E2: 2029 | F2: 2030 | G2: 2031
A4: Key Performance Indicators
A5: Profitability
A6: Net revenue | B6: =Model!E139 -> 1457671.9 | C6: =Model!F139 -> 2765932.4 | D6: =Model!G139 -> 4678875.3 | E6: =Model!H139 -> 7440280.8 | F6: =Model!I139 -> 11388011 | G6: =Model!J139 -> 16989801
A7: Revenue growth % | B7: N/A | C7: =C6/B6-1 -> 0.8975 | D7: =D6/C6-1 -> 0.6916087 | E7: =E6/D6-1 -> 0.59018575 | F7: =F6/E6-1 -> 0.53058883 | G7: =G6/F6-1 -> 0.49190241
A8: Gross profit | B8: =Model!E143 -> 512359.38 | C8: =Model!F143 -> 990139.22 | D8: =Model!G143 -> 1704967.6 | E8: =Model!H143 -> 2758505.8 | F8: =Model!I143 -> 4293796.9 | G8: =Model!J143 -> 6511764.7
A9: Gross margin % | B9: =Model!E144 -> 0.35149157 | C9: =Model!F144 -> 0.35797665 | D9: =Model!G144 -> 0.36439689 | E9: =Model!H144 -> 0.37075292 | F9: =Model!I144 -> 0.37704539 | G9: =Model!J144 -> 0.38327494
A10: EBITDA | B10: =Model!E159 -> 11234.375 | C10: =Model!F159 -> 71085.062 | D10: =Model!G159 -> 589544.71 | E10: =Model!H159 -> 1393903.8 | F10: =Model!I159 -> 2612861.5 | G10: =Model!J159 -> 4429091
A11: EBITDA margin % | B11: =Model!E160 -> 0.0077070671 | C11: =Model!F160 -> 0.025700217 | D11: =Model!G160 -> 0.12600137 | E11: =Model!H160 -> 0.1873456 | F11: =Model!I160 -> 0.22943968 | G11: =Model!J160 -> 0.26069117
A12: Net income | B12: =Model!E167 -> -26578.125 | C12: =Model!F167 -> -38476.656 | D12: =Model!G167 -> 268958.54 | E12: =Model!H167 -> 727475.34 | F12: =Model!I167 -> 1420137 | G12: =Model!J167 -> 2371143.3
A13: Unit Economics
A14: Customer acquisition cost | B14: =Model!E255 -> 38.333333 | C14: =Model!F255 -> 40.25 | D14: =Model!G255 -> 42.2625 | E14: =Model!H255 -> 44.375625 | F14: =Model!I255 -> 46.594406 | G14: =Model!J255 -> 48.924127
A15: Average order value | B15: =Model!E134/Model!E41 -> 250 | C15: =Model!F134/Model!F41 -> 275 | D15: =Model!G134/Model!G41 -> 302.5 | E15: =Model!H134/Model!H41 -> 332.75 | F15: =Model!I134/Model!I41 -> 366.025 | G15: =Model!J134/Model!J41 -> 402.6275
A16: Contribution margin / order | B16: =Model!E256 -> 47.75 | C16: =Model!F256 -> 55.56 | D16: =Model!G256 -> 64.300575 | E16: =Model!H256 -> 74.076218 | F16: =Model!I256 -> 85.002851 | G16: =Model!J256 -> 97.209056
A17: Payback (# of orders) | B17: =Model!E257 -> 0.80279232 | C17: =Model!F257 -> 0.72444204 | D17: =Model!G257 -> 0.65726473 | E17: =Model!H257 -> 0.5990536 | F17: =Model!I257 -> 0.5481511 | G17: =Model!J257 -> 0.50328775
A18: Volume
A19: Total orders | B19: =Model!E41 -> 7562.5 | C19: =Model!F41 -> 13045.312 | D19: =Model!G41 -> 20061.422 | E19: =Model!H41 -> 29001.261 | F19: =Model!I41 -> 40353.642 | G19: =Model!J41 -> 54730.633

Sheet Chart Data
B1: 2026 | C1: 2027 | D1: 2028 | E1: 2029 | F1: 2030 | G1: 2031
A2: Revenue | B2: =Model!E134 -> 1890625 | C2: =Model!F134 -> 3587460.9 | D2: =Model!G134 -> 6068580.1 | E2: =Model!H134 -> 9650169.6 | F2: =Model!I134 -> 14770442 | G2: =Model!J134 -> 22036058
A3: Net income | B3: =Model!E167 -> -26578.125 | C3: =Model!F167 -> -38476.656 | D3: =Model!G167 -> 268958.54 | E3: =Model!H167 -> 727475.34 | F3: =Model!I167 -> 1420137 | G3: =Model!J167 -> 2371143.3
B5: 2026 | C5: 2027 | D5: 2028 | E5: 2029 | F5: 2030 | G5: 2031
A6: Gross margin % | B6: =Model!E144 -> 0.35149157 | C6: =Model!F144 -> 0.35797665 | D6: =Model!G144 -> 0.36439689 | E6: =Model!H144 -> 0.37075292 | F6: =Model!I144 -> 0.37704539 | G6: =Model!J144 -> 0.38327494
A7: EBITDA margin % | B7: =Model!E160 -> 0.0077070671 | C7: =Model!F160 -> 0.025700217 | D7: =Model!G160 -> 0.12600137 | E7: =Model!H160 -> 0.1873456 | F7: =Model!I160 -> 0.22943968 | G7: =Model!J160 -> 0.26069117
A8: Contribution margin % | B8: =Model!E153 -> 0.19842214 | C8: =Model!F153 -> 0.22930245 | D8: =Model!G153 -> 0.25131087 | E8: =Model!H153 -> 0.26941547 | F8: =Model!I153 -> 0.28530142 | G8: =Model!J153 -> 0.29971233
B10: 2026 | C10: 2027 | D10: 2028 | E10: 2029 | F10: 2030 | G10: 2031
A11: CAC | B11: =Model!E255 -> 38.333333 | C11: =Model!F255 -> 40.25 | D11: =Model!G255 -> 42.2625 | E11: =Model!H255 -> 44.375625 | F11: =Model!I255 -> 46.594406 | G11: =Model!J255 -> 48.924127
A12: AOV | B12: =Model!E134/Model!E41 -> 250 | C12: =Model!F134/Model!F41 -> 275 | D12: =Model!G134/Model!G41 -> 302.5 | E12: =Model!H134/Model!H41 -> 332.75 | F12: =Model!I134/Model!I41 -> 366.025 | G12: =Model!J134/Model!J41 -> 402.6275
A13: Contribution margin / order | B13: =Model!E256 -> 47.75 | C13: =Model!F256 -> 55.56 | D13: =Model!G256 -> 64.300575 | E13: =Model!H256 -> 74.076218 | F13: =Model!I256 -> 85.002851 | G13: =Model!J256 -> 97.209056
B15: 2026 | C15: 2027 | D15: 2028 | E15: 2029 | F15: 2030 | G15: 2031
A16: Burn rate | B16: =Model!E258 -> -412547.95 | C16: =Model!F258 -> -446370.34 | D16: =Model!G258 -> -297747.09 | E16: =Model!H258 -> -40976.204 | F16: =Model!I258 -> 393955.59 | G16: =Model!J258 -> 1121357.6
A17: Cash balance | B17: =Model!E222 -> 87452.055 | C17: =Model!F222 -> -358918.29 | D17: =Model!G222 -> -656665.38 | E17: =Model!H222 -> -697641.59 | F17: =Model!I222 -> -303685.99 | G17: =Model!J222 -> 817671.64
